# DevCalc API


Gerei um erro proposital com `run: exit 1` e fiz push, recebendo em **Actions** a mensagem “Process completed with exit code 1”. Em seguida comentei esse step no workflow, dei push de novo e o erro foi eliminado.

